[2021-11-16 11:48:01,980] {taskinstance.py:1035} INFO - Dependencies all met for <TaskInstance: ml_pipeline.get_data manual__2021-11-16T14:47:58.023038+00:00 [queued]>
[2021-11-16 11:48:01,992] {taskinstance.py:1035} INFO - Dependencies all met for <TaskInstance: ml_pipeline.get_data manual__2021-11-16T14:47:58.023038+00:00 [queued]>
[2021-11-16 11:48:01,992] {taskinstance.py:1241} INFO - 
--------------------------------------------------------------------------------
[2021-11-16 11:48:01,992] {taskinstance.py:1242} INFO - Starting attempt 1 of 2
[2021-11-16 11:48:01,993] {taskinstance.py:1243} INFO - 
--------------------------------------------------------------------------------
[2021-11-16 11:48:02,185] {taskinstance.py:1262} INFO - Executing <Task(BashOperator): get_data> on 2021-11-16 14:47:58.023038+00:00
[2021-11-16 11:48:02,188] {standard_task_runner.py:52} INFO - Started process 12294 to run task
[2021-11-16 11:48:02,194] {standard_task_runner.py:76} INFO - Running: ['airflow', 'tasks', 'run', 'ml_pipeline', 'get_data', 'manual__2021-11-16T14:47:58.023038+00:00', '--job-id', '13', '--raw', '--subdir', 'DAGS_FOLDER/ml_dag.py', '--cfg-path', '/tmp/tmp9qt0qfzm', '--error-file', '/tmp/tmp1dxdftew']
[2021-11-16 11:48:02,195] {standard_task_runner.py:77} INFO - Job 13: Subtask get_data
[2021-11-16 11:48:02,287] {logging_mixin.py:109} INFO - Running <TaskInstance: ml_pipeline.get_data manual__2021-11-16T14:47:58.023038+00:00 [running]> on host ana-X550CA
[2021-11-16 11:48:02,510] {taskinstance.py:1427} INFO - Exporting the following env vars:
AIRFLOW_CTX_DAG_OWNER=plbalmeida
AIRFLOW_CTX_DAG_ID=ml_pipeline
AIRFLOW_CTX_TASK_ID=get_data
AIRFLOW_CTX_EXECUTION_DATE=2021-11-16T14:47:58.023038+00:00
AIRFLOW_CTX_DAG_RUN_ID=manual__2021-11-16T14:47:58.023038+00:00
[2021-11-16 11:48:02,511] {subprocess.py:62} INFO - Tmp dir root location: 
 /tmp
[2021-11-16 11:48:02,511] {subprocess.py:74} INFO - Running command: ['bash', '-c', 'python3 /home/ana/Documentos/airflowML/src/data/make_dataset.py']
[2021-11-16 11:48:02,519] {subprocess.py:85} INFO - Output:
[2021-11-16 11:48:03,238] {subprocess.py:89} INFO - Traceback (most recent call last):
[2021-11-16 11:48:03,239] {subprocess.py:89} INFO -   File "/home/ana/Documentos/airflowML/src/data/make_dataset.py", line 69, in <module>
[2021-11-16 11:48:03,239] {subprocess.py:89} INFO -     vendas.to_csv(path + '/data/vendas.csv', index=False)
[2021-11-16 11:48:03,239] {subprocess.py:89} INFO -   File "/home/ana/Documentos/airflowML/venv/lib/python3.8/site-packages/pandas/core/generic.py", line 3466, in to_csv
[2021-11-16 11:48:03,239] {subprocess.py:89} INFO -     return DataFrameRenderer(formatter).to_csv(
[2021-11-16 11:48:03,239] {subprocess.py:89} INFO -   File "/home/ana/Documentos/airflowML/venv/lib/python3.8/site-packages/pandas/io/formats/format.py", line 1105, in to_csv
[2021-11-16 11:48:03,239] {subprocess.py:89} INFO -     csv_formatter.save()
[2021-11-16 11:48:03,239] {subprocess.py:89} INFO -   File "/home/ana/Documentos/airflowML/venv/lib/python3.8/site-packages/pandas/io/formats/csvs.py", line 237, in save
[2021-11-16 11:48:03,239] {subprocess.py:89} INFO -     with get_handle(
[2021-11-16 11:48:03,239] {subprocess.py:89} INFO -   File "/home/ana/Documentos/airflowML/venv/lib/python3.8/site-packages/pandas/io/common.py", line 702, in get_handle
[2021-11-16 11:48:03,239] {subprocess.py:89} INFO -     handle = open(
[2021-11-16 11:48:03,239] {subprocess.py:89} INFO - FileNotFoundError: [Errno 2] No such file or directory: '/tmp/airflowtmpfht9ib91/data/vendas.csv'
[2021-11-16 11:48:03,299] {subprocess.py:93} INFO - Command exited with return code 1
[2021-11-16 11:48:03,316] {taskinstance.py:1703} ERROR - Task failed with exception
Traceback (most recent call last):
  File "/home/ana/Documentos/airflowML/venv/lib/python3.8/site-packages/airflow/models/taskinstance.py", line 1332, in _run_raw_task
    self._execute_task_with_callbacks(context)
  File "/home/ana/Documentos/airflowML/venv/lib/python3.8/site-packages/airflow/models/taskinstance.py", line 1458, in _execute_task_with_callbacks
    result = self._execute_task(context, self.task)
  File "/home/ana/Documentos/airflowML/venv/lib/python3.8/site-packages/airflow/models/taskinstance.py", line 1514, in _execute_task
    result = execute_callable(context=context)
  File "/home/ana/Documentos/airflowML/venv/lib/python3.8/site-packages/airflow/operators/bash.py", line 187, in execute
    raise AirflowException(
airflow.exceptions.AirflowException: Bash command failed. The command returned a non-zero exit code 1.
[2021-11-16 11:48:03,323] {taskinstance.py:1270} INFO - Marking task as UP_FOR_RETRY. dag_id=ml_pipeline, task_id=get_data, execution_date=20211116T144758, start_date=20211116T144801, end_date=20211116T144803
[2021-11-16 11:48:03,403] {standard_task_runner.py:88} ERROR - Failed to execute job 13 for task get_data
Traceback (most recent call last):
  File "/home/ana/Documentos/airflowML/venv/lib/python3.8/site-packages/airflow/task/task_runner/standard_task_runner.py", line 85, in _start_by_fork
    args.func(args, dag=self.dag)
  File "/home/ana/Documentos/airflowML/venv/lib/python3.8/site-packages/airflow/cli/cli_parser.py", line 48, in command
    return func(*args, **kwargs)
  File "/home/ana/Documentos/airflowML/venv/lib/python3.8/site-packages/airflow/utils/cli.py", line 92, in wrapper
    return f(*args, **kwargs)
  File "/home/ana/Documentos/airflowML/venv/lib/python3.8/site-packages/airflow/cli/commands/task_command.py", line 292, in task_run
    _run_task_by_selected_method(args, dag, ti)
  File "/home/ana/Documentos/airflowML/venv/lib/python3.8/site-packages/airflow/cli/commands/task_command.py", line 107, in _run_task_by_selected_method
    _run_raw_task(args, ti)
  File "/home/ana/Documentos/airflowML/venv/lib/python3.8/site-packages/airflow/cli/commands/task_command.py", line 180, in _run_raw_task
    ti._run_raw_task(
  File "/home/ana/Documentos/airflowML/venv/lib/python3.8/site-packages/airflow/utils/session.py", line 70, in wrapper
    return func(*args, session=session, **kwargs)
  File "/home/ana/Documentos/airflowML/venv/lib/python3.8/site-packages/airflow/models/taskinstance.py", line 1332, in _run_raw_task
    self._execute_task_with_callbacks(context)
  File "/home/ana/Documentos/airflowML/venv/lib/python3.8/site-packages/airflow/models/taskinstance.py", line 1458, in _execute_task_with_callbacks
    result = self._execute_task(context, self.task)
  File "/home/ana/Documentos/airflowML/venv/lib/python3.8/site-packages/airflow/models/taskinstance.py", line 1514, in _execute_task
    result = execute_callable(context=context)
  File "/home/ana/Documentos/airflowML/venv/lib/python3.8/site-packages/airflow/operators/bash.py", line 187, in execute
    raise AirflowException(
airflow.exceptions.AirflowException: Bash command failed. The command returned a non-zero exit code 1.
[2021-11-16 11:48:03,450] {local_task_job.py:154} INFO - Task exited with return code 1
[2021-11-16 11:48:03,478] {local_task_job.py:264} INFO - 0 downstream tasks scheduled from follow-on schedule check
