[2021-11-16 11:16:01,928] {taskinstance.py:1035} INFO - Dependencies all met for <TaskInstance: ml_pipeline.get_data scheduled__2021-11-15T00:00:00+00:00 [queued]>
[2021-11-16 11:16:01,935] {taskinstance.py:1035} INFO - Dependencies all met for <TaskInstance: ml_pipeline.get_data scheduled__2021-11-15T00:00:00+00:00 [queued]>
[2021-11-16 11:16:01,935] {taskinstance.py:1241} INFO - 
--------------------------------------------------------------------------------
[2021-11-16 11:16:01,936] {taskinstance.py:1242} INFO - Starting attempt 2 of 2
[2021-11-16 11:16:01,936] {taskinstance.py:1243} INFO - 
--------------------------------------------------------------------------------
[2021-11-16 11:16:02,091] {taskinstance.py:1262} INFO - Executing <Task(BashOperator): get_data> on 2021-11-15 00:00:00+00:00
[2021-11-16 11:16:02,093] {standard_task_runner.py:52} INFO - Started process 9802 to run task
[2021-11-16 11:16:02,099] {standard_task_runner.py:76} INFO - Running: ['airflow', 'tasks', 'run', 'ml_pipeline', 'get_data', 'scheduled__2021-11-15T00:00:00+00:00', '--job-id', '4', '--raw', '--subdir', 'DAGS_FOLDER/ml_dag.py', '--cfg-path', '/tmp/tmp4vli9d5o', '--error-file', '/tmp/tmpp5riyo3p']
[2021-11-16 11:16:02,100] {standard_task_runner.py:77} INFO - Job 4: Subtask get_data
[2021-11-16 11:16:02,279] {logging_mixin.py:109} INFO - Running <TaskInstance: ml_pipeline.get_data scheduled__2021-11-15T00:00:00+00:00 [running]> on host ana-X550CA
[2021-11-16 11:16:02,398] {taskinstance.py:1427} INFO - Exporting the following env vars:
AIRFLOW_CTX_DAG_OWNER=plbalmeida
AIRFLOW_CTX_DAG_ID=ml_pipeline
AIRFLOW_CTX_TASK_ID=get_data
AIRFLOW_CTX_EXECUTION_DATE=2021-11-15T00:00:00+00:00
AIRFLOW_CTX_DAG_RUN_ID=scheduled__2021-11-15T00:00:00+00:00
[2021-11-16 11:16:02,399] {subprocess.py:62} INFO - Tmp dir root location: 
 /tmp
[2021-11-16 11:16:02,399] {subprocess.py:74} INFO - Running command: ['bash', '-c', 'python /home/ana/Documentos/airflowML/src/data/make_dataset.py']
[2021-11-16 11:16:02,409] {subprocess.py:85} INFO - Output:
[2021-11-16 11:16:02,893] {subprocess.py:89} INFO - Traceback (most recent call last):
[2021-11-16 11:16:02,893] {subprocess.py:89} INFO -   File "/home/ana/Documentos/airflowML/src/data/make_dataset.py", line 66, in <module>
[2021-11-16 11:16:02,893] {subprocess.py:89} INFO -     if len(os.listdir(os.getcwd() + '/data/raw')) == 0:
[2021-11-16 11:16:02,894] {subprocess.py:89} INFO - FileNotFoundError: [Errno 2] No such file or directory: '/tmp/airflowtmpokf39lfo/data/raw'
[2021-11-16 11:16:02,954] {subprocess.py:93} INFO - Command exited with return code 1
[2021-11-16 11:16:02,968] {taskinstance.py:1703} ERROR - Task failed with exception
Traceback (most recent call last):
  File "/home/ana/Documentos/airflowML/venv/lib/python3.8/site-packages/airflow/models/taskinstance.py", line 1332, in _run_raw_task
    self._execute_task_with_callbacks(context)
  File "/home/ana/Documentos/airflowML/venv/lib/python3.8/site-packages/airflow/models/taskinstance.py", line 1458, in _execute_task_with_callbacks
    result = self._execute_task(context, self.task)
  File "/home/ana/Documentos/airflowML/venv/lib/python3.8/site-packages/airflow/models/taskinstance.py", line 1514, in _execute_task
    result = execute_callable(context=context)
  File "/home/ana/Documentos/airflowML/venv/lib/python3.8/site-packages/airflow/operators/bash.py", line 187, in execute
    raise AirflowException(
airflow.exceptions.AirflowException: Bash command failed. The command returned a non-zero exit code 1.
[2021-11-16 11:16:02,974] {taskinstance.py:1270} INFO - Marking task as FAILED. dag_id=ml_pipeline, task_id=get_data, execution_date=20211115T000000, start_date=20211116T141601, end_date=20211116T141602
[2021-11-16 11:16:03,121] {standard_task_runner.py:88} ERROR - Failed to execute job 4 for task get_data
Traceback (most recent call last):
  File "/home/ana/Documentos/airflowML/venv/lib/python3.8/site-packages/airflow/task/task_runner/standard_task_runner.py", line 85, in _start_by_fork
    args.func(args, dag=self.dag)
  File "/home/ana/Documentos/airflowML/venv/lib/python3.8/site-packages/airflow/cli/cli_parser.py", line 48, in command
    return func(*args, **kwargs)
  File "/home/ana/Documentos/airflowML/venv/lib/python3.8/site-packages/airflow/utils/cli.py", line 92, in wrapper
    return f(*args, **kwargs)
  File "/home/ana/Documentos/airflowML/venv/lib/python3.8/site-packages/airflow/cli/commands/task_command.py", line 292, in task_run
    _run_task_by_selected_method(args, dag, ti)
  File "/home/ana/Documentos/airflowML/venv/lib/python3.8/site-packages/airflow/cli/commands/task_command.py", line 107, in _run_task_by_selected_method
    _run_raw_task(args, ti)
  File "/home/ana/Documentos/airflowML/venv/lib/python3.8/site-packages/airflow/cli/commands/task_command.py", line 180, in _run_raw_task
    ti._run_raw_task(
  File "/home/ana/Documentos/airflowML/venv/lib/python3.8/site-packages/airflow/utils/session.py", line 70, in wrapper
    return func(*args, session=session, **kwargs)
  File "/home/ana/Documentos/airflowML/venv/lib/python3.8/site-packages/airflow/models/taskinstance.py", line 1332, in _run_raw_task
    self._execute_task_with_callbacks(context)
  File "/home/ana/Documentos/airflowML/venv/lib/python3.8/site-packages/airflow/models/taskinstance.py", line 1458, in _execute_task_with_callbacks
    result = self._execute_task(context, self.task)
  File "/home/ana/Documentos/airflowML/venv/lib/python3.8/site-packages/airflow/models/taskinstance.py", line 1514, in _execute_task
    result = execute_callable(context=context)
  File "/home/ana/Documentos/airflowML/venv/lib/python3.8/site-packages/airflow/operators/bash.py", line 187, in execute
    raise AirflowException(
airflow.exceptions.AirflowException: Bash command failed. The command returned a non-zero exit code 1.
[2021-11-16 11:16:03,154] {local_task_job.py:154} INFO - Task exited with return code 1
[2021-11-16 11:16:03,267] {local_task_job.py:264} INFO - 0 downstream tasks scheduled from follow-on schedule check
